<mujoco model="g1_29dof_rev_1_0_with_inspire_hand_FTP">
  <compiler angle="radian" meshdir="meshes/"/>

  <default>
      <default class="torso_motor">
          <joint damping="0.05" armature="0.01" frictionloss="0.2"/>
      </default>
      <default class="leg_motor">
          <joint damping="0.05" armature="0.01" frictionloss="0.2"/>
      </default>
      <default class="ankle_motor">
          <joint damping="0.05" armature="0.01" frictionloss="0.2"/>
      </default>
      <default class="arm_motor">
          <joint damping="0.05" armature="0.01" frictionloss="0.2"/>
      </default>
      <default class="wrist_motor">
          <joint damping="0.05" armature="0.01" frictionloss="0.1"/>
      </default>

  </default>



  <asset>
    <mesh name="pelvis" content_type="model/stl" file="pelvis.STL"/>
    <mesh name="pelvis_contour_link" content_type="model/stl" file="pelvis_contour_link.STL"/>
    <mesh name="left_hip_pitch_link" content_type="model/stl" file="left_hip_pitch_link.STL"/>
    <mesh name="left_hip_roll_link" content_type="model/stl" file="left_hip_roll_link.STL"/>
    <mesh name="left_hip_yaw_link" content_type="model/stl" file="left_hip_yaw_link.STL"/>
    <mesh name="left_knee_link" content_type="model/stl" file="left_knee_link.STL"/>
    <mesh name="left_ankle_pitch_link" content_type="model/stl" file="left_ankle_pitch_link.STL"/>
    <mesh name="left_ankle_roll_link" content_type="model/stl" file="left_ankle_roll_link.STL"/>
    <mesh name="right_hip_pitch_link" content_type="model/stl" file="right_hip_pitch_link.STL"/>
    <mesh name="right_hip_roll_link" content_type="model/stl" file="right_hip_roll_link.STL"/>
    <mesh name="right_hip_yaw_link" content_type="model/stl" file="right_hip_yaw_link.STL"/>
    <mesh name="right_knee_link" content_type="model/stl" file="right_knee_link.STL"/>
    <mesh name="right_ankle_pitch_link" content_type="model/stl" file="right_ankle_pitch_link.STL"/>
    <mesh name="right_ankle_roll_link" content_type="model/stl" file="right_ankle_roll_link.STL"/>
    <mesh name="waist_yaw_link_rev_1_0" content_type="model/stl" file="waist_yaw_link_rev_1_0.STL"/>
    <mesh name="waist_roll_link_rev_1_0" content_type="model/stl" file="waist_roll_link_rev_1_0.STL"/>
    <mesh name="torso_link_rev_1_0" content_type="model/stl" file="torso_link_rev_1_0.STL"/>
    <mesh name="logo_link" content_type="model/stl" file="logo_link.STL"/>
    <mesh name="head_link" content_type="model/stl" file="head_link.STL"/>
    <mesh name="left_shoulder_pitch_link" content_type="model/stl" file="left_shoulder_pitch_link.STL"/>
    <mesh name="left_shoulder_roll_link" content_type="model/stl" file="left_shoulder_roll_link.STL"/>
    <mesh name="left_shoulder_yaw_link" content_type="model/stl" file="left_shoulder_yaw_link.STL"/>
    <mesh name="left_elbow_link" content_type="model/stl" file="left_elbow_link.STL"/>
    <mesh name="left_wrist_roll_link" content_type="model/stl" file="left_wrist_roll_link.STL"/>
    <mesh name="left_wrist_pitch_link" content_type="model/stl" file="left_wrist_pitch_link.STL"/>
    <mesh name="left_wrist_yaw_link" content_type="model/stl" file="left_wrist_yaw_link.STL"/>
    <mesh name="right_shoulder_pitch_link" content_type="model/stl" file="right_shoulder_pitch_link.STL"/>
    <mesh name="right_shoulder_roll_link" content_type="model/stl" file="right_shoulder_roll_link.STL"/>
    <mesh name="right_shoulder_yaw_link" content_type="model/stl" file="right_shoulder_yaw_link.STL"/>
    <mesh name="right_elbow_link" content_type="model/stl" file="right_elbow_link.STL"/>
    <mesh name="right_wrist_roll_link" content_type="model/stl" file="right_wrist_roll_link.STL"/>
    <mesh name="right_wrist_pitch_link" content_type="model/stl" file="right_wrist_pitch_link.STL"/>
    <mesh name="right_wrist_yaw_link" content_type="model/stl" file="right_wrist_yaw_link.STL"/>
    <mesh name="left_base_link" content_type="model/stl" file="left_base_link.STL"/>
    <mesh name="left_palm_force_sensor" content_type="model/stl" file="left_palm_force_sensor.STL"/>
    <mesh name="left_thumb_1" content_type="model/stl" file="left_thumb_1.STL"/>
    <mesh name="left_thumb_2" content_type="model/stl" file="left_thumb_2.STL"/>
    <mesh name="left_thumb_force_sensor_1" content_type="model/stl" file="left_thumb_force_sensor_1.STL"/>
    <mesh name="left_thumb_3" content_type="model/stl" file="left_thumb_3.STL"/>
    <mesh name="left_thumb_force_sensor_2" content_type="model/stl" file="left_thumb_force_sensor_2.STL"/>
    <mesh name="left_thumb_4" content_type="model/stl" file="left_thumb_4.STL"/>
    <mesh name="left_thumb_force_sensor_3" content_type="model/stl" file="left_thumb_force_sensor_3.STL"/>
    <mesh name="left_thumb_force_sensor_4" content_type="model/stl" file="left_thumb_force_sensor_4.STL"/>
    <mesh name="left_index_1" content_type="model/stl" file="left_index_1.STL"/>
    <mesh name="left_index_force_sensor_1" content_type="model/stl" file="left_index_force_sensor_1.STL"/>
    <mesh name="left_index_2" content_type="model/stl" file="left_index_2.STL"/>
    <mesh name="left_index_force_sensor_2" content_type="model/stl" file="left_index_force_sensor_2.STL"/>
    <mesh name="left_index_force_sensor_3" content_type="model/stl" file="left_index_force_sensor_3.STL"/>
    <mesh name="left_middle_1" content_type="model/stl" file="left_middle_1.STL"/>
    <mesh name="left_middle_force_sensor_1" content_type="model/stl" file="left_middle_force_sensor_1.STL"/>
    <mesh name="left_middle_2" content_type="model/stl" file="left_middle_2.STL"/>
    <mesh name="left_middle_force_sensor_2" content_type="model/stl" file="left_middle_force_sensor_2.STL"/>
    <mesh name="left_middle_force_sensor_3" content_type="model/stl" file="left_middle_force_sensor_3.STL"/>
    <mesh name="left_ring_1" content_type="model/stl" file="left_ring_1.STL"/>
    <mesh name="left_ring_force_sensor_1" content_type="model/stl" file="left_ring_force_sensor_1.STL"/>
    <mesh name="left_ring_2" content_type="model/stl" file="left_ring_2.STL"/>
    <mesh name="left_ring_force_sensor_2" content_type="model/stl" file="left_ring_force_sensor_2.STL"/>
    <mesh name="left_ring_force_sensor_3" content_type="model/stl" file="left_ring_force_sensor_3.STL"/>
    <mesh name="left_little_1" content_type="model/stl" file="left_little_1.STL"/>
    <mesh name="left_little_force_sensor_1" content_type="model/stl" file="left_little_force_sensor_1.STL"/>
    <mesh name="left_little_2" content_type="model/stl" file="left_little_2.STL"/>
    <mesh name="left_little_force_sensor_2" content_type="model/stl" file="left_little_force_sensor_2.STL"/>
    <mesh name="left_little_force_sensor_3" content_type="model/stl" file="left_little_force_sensor_3.STL"/>
    <mesh name="right_base_link" content_type="model/stl" file="right_base_link.STL"/>
    <mesh name="right_palm_force_sensor" content_type="model/stl" file="right_palm_force_sensor.STL"/>
    <mesh name="right_thumb_1" content_type="model/stl" file="right_thumb_1.STL"/>
    <mesh name="right_thumb_2" content_type="model/stl" file="right_thumb_2.STL"/>
    <mesh name="right_thumb_3" content_type="model/stl" file="right_thumb_3.STL"/>
    <mesh name="right_thumb_force_sensor_2" content_type="model/stl" file="right_thumb_force_sensor_2.STL"/>
    <mesh name="right_thumb_4" content_type="model/stl" file="right_thumb_4.STL"/>
    <mesh name="right_thumb_force_sensor_3" content_type="model/stl" file="right_thumb_force_sensor_3.STL"/>
    <mesh name="right_thumb_force_sensor_4" content_type="model/stl" file="right_thumb_force_sensor_4.STL"/>
    <mesh name="right_thumb_force_sensor_1" content_type="model/stl" file="right_thumb_force_sensor_1.STL"/>
    <mesh name="right_index_1" content_type="model/stl" file="right_index_1.STL"/>
    <mesh name="right_index_2" content_type="model/stl" file="right_index_2.STL"/>
    <mesh name="right_index_force_sensor_2" content_type="model/stl" file="right_index_force_sensor_2.STL"/>
    <mesh name="right_index_force_sensor_3" content_type="model/stl" file="right_index_force_sensor_3.STL"/>
    <mesh name="right_index_force_sensor_1" content_type="model/stl" file="right_index_force_sensor_1.STL"/>
    <mesh name="right_middle_1" content_type="model/stl" file="right_middle_1.STL"/>
    <mesh name="right_middle_2" content_type="model/stl" file="right_middle_2.STL"/>
    <mesh name="right_middle_force_sensor_2" content_type="model/stl" file="right_middle_force_sensor_2.STL"/>
    <mesh name="right_middle_force_sensor_3" content_type="model/stl" file="right_middle_force_sensor_3.STL"/>
    <mesh name="right_middle_force_sensor_1" content_type="model/stl" file="right_middle_force_sensor_1.STL"/>
    <mesh name="right_ring_1" content_type="model/stl" file="right_ring_1.STL"/>
    <mesh name="right_ring_2" content_type="model/stl" file="right_ring_2.STL"/>
    <mesh name="right_ring_force_sensor_2" content_type="model/stl" file="right_ring_force_sensor_2.STL"/>
    <mesh name="right_ring_force_sensor_3" content_type="model/stl" file="right_ring_force_sensor_3.STL"/>
    <mesh name="right_ring_force_sensor_1" content_type="model/stl" file="right_ring_force_sensor_1.STL"/>
    <mesh name="right_little_1" content_type="model/stl" file="right_little_1.STL"/>
    <mesh name="right_little_2" content_type="model/stl" file="right_little_2.STL"/>
    <mesh name="right_little_force_sensor_2" content_type="model/stl" file="right_little_force_sensor_2.STL"/>
    <mesh name="right_little_force_sensor_3" content_type="model/stl" file="right_little_force_sensor_3.STL"/>
    <mesh name="right_little_force_sensor_1" content_type="model/stl" file="right_little_force_sensor_1.STL"/>
  </asset>

  <worldbody>
    <body name="pelvis" pos="0 0 0.793">
      <site name="imu" size="0.01" pos="0.0 0.0 0.0"/>
      <inertial pos="0 0 -0.07605" quat="1 0 -0.000399148 0" mass="3.813"
                diaginertia="0.010549 0.0093089 0.0079184"/>
      <joint name="floating_base_joint" type="free" limited="false" actuatorfrclimited="false"/>

      <geom type="mesh" contype="0" conaffinity="0" group="1" density="0" rgba="0.2 0.2 0.2 1" mesh="pelvis"/>
      <geom type="mesh" contype="0" conaffinity="0" group="1" density="0" rgba="0.7 0.7 0.7 1" mesh="pelvis_contour_link"/>
      <geom type="mesh" rgba="0.7 0.7 0.7 1" mesh="pelvis_contour_link"/>
      <body name="left_hip_pitch_link" pos="0 0.064452 -0.1027">
        <inertial pos="0.002741 0.047791 -0.02606" quat="0.954862 0.293964 0.0302556 0.030122" mass="1.35" diaginertia="0.00181517 0.00153422 0.00116212"/>
        <joint name="left_hip_pitch_joint" pos="0 0 0" axis="0 1 0" range="-2.5307 2.8798" actuatorfrcrange="-88 88" class="leg_motor"/>
        <geom type="mesh" contype="0" conaffinity="0" group="1" density="0" rgba="0.2 0.2 0.2 1" mesh="left_hip_pitch_link"/>
        <geom type="mesh" rgba="0.2 0.2 0.2 1" mesh="left_hip_pitch_link"/>
        <body name="left_hip_roll_link" pos="0 0.052 -0.030465" quat="0.996179 0 -0.0873386 0">
          <inertial pos="0.029812 -0.001045 -0.087934" quat="0.977808 -1.97119e-05 0.205576 -0.0403793" mass="1.52" diaginertia="0.00254986 0.00241169 0.00148755"/>
          <joint name="left_hip_roll_joint" pos="0 0 0" axis="1 0 0" range="-0.5236 2.9671" actuatorfrcrange="-139 139" class="leg_motor"/>
          <geom type="mesh" contype="0" conaffinity="0" group="1" density="0" rgba="0.7 0.7 0.7 1" mesh="left_hip_roll_link"/>
          <geom type="mesh" rgba="0.7 0.7 0.7 1" mesh="left_hip_roll_link"/>
          <body name="left_hip_yaw_link" pos="0.025001 0 -0.12412">
            <inertial pos="-0.057709 -0.010981 -0.15078" quat="0.600598 0.15832 0.223482 0.751181" mass="1.702" diaginertia="0.00776166 0.00717575 0.00160139"/>
            <joint name="left_hip_yaw_joint" pos="0 0 0" axis="0 0 1" range="-2.7576 2.7576" actuatorfrcrange="-88 88" class="leg_motor"/>
            <geom type="mesh" contype="0" conaffinity="0" group="1" density="0" rgba="0.7 0.7 0.7 1" mesh="left_hip_yaw_link"/>
            <geom type="mesh" rgba="0.7 0.7 0.7 1" mesh="left_hip_yaw_link"/>
            <body name="left_knee_link" pos="-0.078273 0.0021489 -0.17734" quat="0.996179 0 0.0873386 0">
              <inertial pos="0.005457 0.003964 -0.12074" quat="0.923418 -0.0327699 0.0158246 0.382067" mass="1.932" diaginertia="0.0113804 0.0112778 0.00146458"/>
              <joint name="left_knee_joint" pos="0 0 0" axis="0 1 0" range="-0.087267 2.8798" actuatorfrcrange="-139 139" class="leg_motor"/>
              <geom type="mesh" contype="0" conaffinity="0" group="1" density="0" rgba="0.7 0.7 0.7 1" mesh="left_knee_link"/>
              <geom type="mesh" rgba="0.7 0.7 0.7 1" mesh="left_knee_link"/>
              <body name="left_ankle_pitch_link" pos="0 -9.4445e-05 -0.30001">
                <inertial pos="-0.007269 0 0.011137" quat="0.603053 0.369225 0.369225 0.603053" mass="0.074" diaginertia="1.89e-05 1.40805e-05 6.9195e-06"/>
                <joint name="left_ankle_pitch_joint" pos="0 0 0" axis="0 1 0" range="-0.87267 0.5236" actuatorfrcrange="-35 35" class="ankle_motor"/>
                <geom type="mesh" contype="0" conaffinity="0" group="1" density="0" rgba="0.7 0.7 0.7 1" mesh="left_ankle_pitch_link"/>
                <geom type="mesh" rgba="0.7 0.7 0.7 1" mesh="left_ankle_pitch_link"/>
                <body name="left_ankle_roll_link" pos="0 0 -0.017558">
                  <inertial pos="0.026505 0 -0.016425" quat="-0.000481092 0.728482 -0.000618967 0.685065" mass="0.608" diaginertia="0.00167218 0.0016161 0.000217621"/>
                  <joint name="left_ankle_roll_joint" pos="0 0 0" axis="1 0 0" range="-0.2618 0.2618" actuatorfrcrange="-35 35" class="ankle_motor"/>
                  <geom type="mesh" contype="0" conaffinity="0" group="1" density="0" rgba="0.2 0.2 0.2 1" mesh="left_ankle_roll_link"/>
                  <geom size="0.005" pos="-0.05 0.025 -0.03" rgba="0.2 0.2 0.2 1"/>
                  <geom size="0.005" pos="-0.05 -0.025 -0.03" rgba="0.2 0.2 0.2 1"/>
                  <geom size="0.005" pos="0.12 0.03 -0.03" rgba="0.2 0.2 0.2 1"/>
                  <geom size="0.005" pos="0.12 -0.03 -0.03" rgba="0.2 0.2 0.2 1"/>
                </body>
              </body>
            </body>
          </body>
        </body>
      </body>
      <body name="right_hip_pitch_link" pos="0 -0.064452 -0.1027">
        <inertial pos="0.002741 -0.047791 -0.02606" quat="0.954862 -0.293964 0.0302556 -0.030122" mass="1.35" diaginertia="0.00181517 0.00153422 0.00116212"/>
        <joint name="right_hip_pitch_joint" pos="0 0 0" axis="0 1 0" range="-2.5307 2.8798" actuatorfrcrange="-88 88" class="leg_motor"/>
        <geom type="mesh" contype="0" conaffinity="0" group="1" density="0" rgba="0.2 0.2 0.2 1" mesh="right_hip_pitch_link"/>
        <geom type="mesh" rgba="0.2 0.2 0.2 1" mesh="right_hip_pitch_link"/>
        <body name="right_hip_roll_link" pos="0 -0.052 -0.030465" quat="0.996179 0 -0.0873386 0">
          <inertial pos="0.029812 0.001045 -0.087934" quat="0.977808 1.97119e-05 0.205576 0.0403793" mass="1.52" diaginertia="0.00254986 0.00241169 0.00148755"/>
          <joint name="right_hip_roll_joint" pos="0 0 0" axis="1 0 0" range="-2.9671 0.5236" actuatorfrcrange="-139 139" class="leg_motor"/>
          <geom type="mesh" contype="0" conaffinity="0" group="1" density="0" rgba="0.7 0.7 0.7 1" mesh="right_hip_roll_link"/>
          <geom type="mesh" rgba="0.7 0.7 0.7 1" mesh="right_hip_roll_link"/>
          <body name="right_hip_yaw_link" pos="0.025001 0 -0.12412">
            <inertial pos="-0.057709 0.010981 -0.15078" quat="0.751181 0.223482 0.15832 0.600598" mass="1.702" diaginertia="0.00776166 0.00717575 0.00160139"/>
            <joint name="right_hip_yaw_joint" pos="0 0 0" axis="0 0 1" range="-2.7576 2.7576" actuatorfrcrange="-88 88" class="leg_motor"/>
            <geom type="mesh" contype="0" conaffinity="0" group="1" density="0" rgba="0.7 0.7 0.7 1" mesh="right_hip_yaw_link"/>
            <geom type="mesh" rgba="0.7 0.7 0.7 1" mesh="right_hip_yaw_link"/>
            <body name="right_knee_link" pos="-0.078273 -0.0021489 -0.17734" quat="0.996179 0 0.0873386 0">
              <inertial pos="0.005457 -0.003964 -0.12074" quat="0.923439 0.0345276 0.0116333 -0.382012" mass="1.932" diaginertia="0.011374 0.0112843 0.00146452"/>
              <joint name="right_knee_joint" pos="0 0 0" axis="0 1 0" range="-0.087267 2.8798" actuatorfrcrange="-139 139" class="leg_motor"/>
              <geom type="mesh" contype="0" conaffinity="0" group="1" density="0" rgba="0.7 0.7 0.7 1" mesh="right_knee_link"/>
              <geom type="mesh" rgba="0.7 0.7 0.7 1" mesh="right_knee_link"/>
              <body name="right_ankle_pitch_link" pos="0 9.4445e-05 -0.30001">
                <inertial pos="-0.007269 0 0.011137" quat="0.603053 0.369225 0.369225 0.603053" mass="0.074" diaginertia="1.89e-05 1.40805e-05 6.9195e-06"/>
                <joint name="right_ankle_pitch_joint" pos="0 0 0" axis="0 1 0" range="-0.87267 0.5236" actuatorfrcrange="-35 35" class="ankle_motor"/>
                <geom type="mesh" contype="0" conaffinity="0" group="1" density="0" rgba="0.7 0.7 0.7 1" mesh="right_ankle_pitch_link"/>
                <geom type="mesh" rgba="0.7 0.7 0.7 1" mesh="right_ankle_pitch_link"/>
                <body name="right_ankle_roll_link" pos="0 0 -0.017558">
                  <inertial pos="0.026505 0 -0.016425" quat="0.000481092 0.728482 0.000618967 0.685065" mass="0.608" diaginertia="0.00167218 0.0016161 0.000217621"/>
                  <joint name="right_ankle_roll_joint" pos="0 0 0" axis="1 0 0" range="-0.2618 0.2618" actuatorfrcrange="-35 35" class="ankle_motor"/>
                  <geom type="mesh" contype="0" conaffinity="0" group="1" density="0" rgba="0.2 0.2 0.2 1" mesh="right_ankle_roll_link"/>
                  <geom size="0.005" pos="-0.05 0.025 -0.03" rgba="0.2 0.2 0.2 1"/>
                  <geom size="0.005" pos="-0.05 -0.025 -0.03" rgba="0.2 0.2 0.2 1"/>
                  <geom size="0.005" pos="0.12 0.03 -0.03" rgba="0.2 0.2 0.2 1"/>
                  <geom size="0.005" pos="0.12 -0.03 -0.03" rgba="0.2 0.2 0.2 1"/>
                </body>
              </body>
            </body>
          </body>
        </body>
      </body>
      <body name="waist_yaw_link">
        <inertial pos="0.003494 0.000233 0.018034" quat="0.289697 0.591001 -0.337795 0.672821" mass="0.214" diaginertia="0.000163531 0.000107714 0.000102205"/>
        <joint name="waist_yaw_joint" pos="0 0 0" axis="0 0 1" range="-2.618 2.618" actuatorfrcrange="-88 88" class="torso_motor"/>
        <geom type="mesh" contype="0" conaffinity="0" group="1" density="0" rgba="0.7 0.7 0.7 1" mesh="waist_yaw_link_rev_1_0"/>
        <body name="waist_roll_link" pos="-0.0039635 0 0.044">
          <inertial pos="0 2.3e-05 0" quat="0.5 0.5 -0.5 0.5" mass="0.086" diaginertia="8.245e-06 7.079e-06 6.339e-06"/>
          <joint name="waist_roll_joint" pos="0 0 0" axis="1 0 0" range="-0.52 0.52" actuatorfrcrange="-35 35" class="torso_motor"/>
          <geom type="mesh" contype="0" conaffinity="0" group="1" density="0" rgba="0.7 0.7 0.7 1" mesh="waist_roll_link_rev_1_0"/>
          <body name="torso_link">
            <inertial pos="0.0013154 0.000855537 0.184599" quat="0.999895 -0.00548212 0.0132901 0.00194196" mass="7.817" diaginertia="0.121734 0.109736 0.0274043"/>
            <joint name="waist_pitch_joint" pos="0 0 0" axis="0 1 0" range="-0.52 0.52" actuatorfrcrange="-35 35" class="torso_motor"/>
            <geom type="mesh" contype="0" conaffinity="0" group="1" density="0" rgba="0.7 0.7 0.7 1" mesh="torso_link_rev_1_0"/>
            <geom type="mesh" rgba="0.7 0.7 0.7 1" mesh="torso_link_rev_1_0"/>
            <geom pos="0.0039635 0 -0.044" quat="1 0 0 0" type="mesh" contype="0" conaffinity="0" group="1" density="0" rgba="0.2 0.2 0.2 1" mesh="logo_link"/>
            <geom pos="0.0039635 0 -0.044" quat="1 0 0 0" type="mesh" rgba="0.2 0.2 0.2 1" mesh="logo_link"/>
            <geom pos="0.0039635 0 -0.044" type="mesh" contype="0" conaffinity="0" group="1" density="0" rgba="0.2 0.2 0.2 1" mesh="head_link"/>
            <geom pos="0.0039635 0 -0.044" type="mesh" rgba="0.2 0.2 0.2 1" mesh="head_link"/>
            <body name="left_shoulder_pitch_link" pos="0.0039563 0.10022 0.24778" quat="0.990264 0.139201 1.38722e-05 -9.86868e-05">
              <inertial pos="0 0.035892 -0.011628" quat="0.654152 0.0130458 -0.326267 0.68225" mass="0.718" diaginertia="0.000465864 0.000432842 0.000406394"/>
              <joint name="left_shoulder_pitch_joint" pos="0 0 0" axis="0 1 0" range="-3.0892 2.6704" actuatorfrcrange="-25 25" class="arm_motor"/>
              <geom type="mesh" contype="0" conaffinity="0" group="1" density="0" rgba="0.7 0.7 0.7 1" mesh="left_shoulder_pitch_link"/>
              <geom size="0.03 0.025" pos="0 0.04 -0.01" quat="0.707107 0 0.707107 0" type="cylinder" rgba="0.7 0.7 0.7 1"/>
              <body name="left_shoulder_roll_link" pos="0 0.038 -0.013831" quat="0.990268 -0.139172 0 0">
                <inertial pos="-0.000227 0.00727 -0.063243" quat="0.701256 -0.0196223 -0.00710317 0.712604" mass="0.643" diaginertia="0.000691311 0.000618011 0.000388977"/>
                <joint name="left_shoulder_roll_joint" pos="0 0 0" axis="1 0 0" range="-1.5882 2.2515" actuatorfrcrange="-25 25" class="arm_motor"/>
                <geom type="mesh" contype="0" conaffinity="0" group="1" density="0" rgba="0.7 0.7 0.7 1" mesh="left_shoulder_roll_link"/>
                <geom size="0.03 0.015" pos="-0.004 0.006 -0.053" type="cylinder" rgba="0.7 0.7 0.7 1"/>
                <body name="left_shoulder_yaw_link" pos="0 0.00624 -0.1032">
                  <inertial pos="0.010773 -0.002949 -0.072009" quat="0.716879 -0.0964829 -0.0679942 0.687134" mass="0.734" diaginertia="0.00106187 0.00103217 0.000400661"/>
                  <joint name="left_shoulder_yaw_joint" pos="0 0 0" axis="0 0 1" range="-2.618 2.618" actuatorfrcrange="-25 25" class="arm_motor"/>
                  <geom type="mesh" contype="0" conaffinity="0" group="1" density="0" rgba="0.7 0.7 0.7 1" mesh="left_shoulder_yaw_link"/>
                  <geom type="mesh" rgba="0.7 0.7 0.7 1" mesh="left_shoulder_yaw_link"/>
                  <body name="left_elbow_link" pos="0.015783 0 -0.080518">
                    <inertial pos="0.064956 0.004454 -0.010062" quat="0.541765 0.636132 0.388821 0.388129" mass="0.6" diaginertia="0.000443035 0.000421612 0.000259353"/>
                    <joint name="left_elbow_joint" pos="0 0 0" axis="0 1 0" range="-1.0472 2.0944" actuatorfrcrange="-25 25" class="arm_motor"/>
                    <geom type="mesh" contype="0" conaffinity="0" group="1" density="0" rgba="0.7 0.7 0.7 1" mesh="left_elbow_link"/>
                    <geom type="mesh" rgba="0.7 0.7 0.7 1" mesh="left_elbow_link"/>
                    <body name="left_wrist_roll_link" pos="0.1 0.00188791 -0.01">
                      <inertial pos="0.0171394 0.000537591 4.8864e-07" quat="0.575338 0.411667 -0.574906 0.411094" mass="0.085445" diaginertia="5.48211e-05 4.96646e-05 3.57798e-05"/>
                      <joint name="left_wrist_roll_joint" pos="0 0 0" axis="1 0 0" range="-1.97222 1.97222" actuatorfrcrange="-25 25" class="arm_motor"/>
                      <geom type="mesh" contype="0" conaffinity="0" group="1" density="0" rgba="0.7 0.7 0.7 1" mesh="left_wrist_roll_link"/>
                      <geom type="mesh" rgba="0.7 0.7 0.7 1" mesh="left_wrist_roll_link"/>
                      <body name="left_wrist_pitch_link" pos="0.038 0 0">
                        <inertial pos="0.0229999 -0.00111685 -0.00111658" quat="0.249998 0.661363 0.293036 0.643608" mass="0.48405" diaginertia="0.000430353 0.000429873 0.000164648"/>
                        <joint name="left_wrist_pitch_joint" pos="0 0 0" axis="0 1 0" range="-1.61443 1.61443" actuatorfrcrange="-5 5" class="wrist_motor"/>
                        <geom type="mesh" contype="0" conaffinity="0" group="1" density="0" rgba="0.7 0.7 0.7 1" mesh="left_wrist_pitch_link"/>
                        <geom type="mesh" rgba="0.7 0.7 0.7 1" mesh="left_wrist_pitch_link"/>
                        <body name="left_wrist_yaw_link" pos="0.046 0 0">
                          <inertial pos="0.00338572 0.0330314 0.0771588" quat="0.808954 -0.185041 0.00260046 0.557985" mass="0.708236" diaginertia="0.00100426 0.000968361 0.000205318"/>
                          <joint name="left_wrist_yaw_joint" pos="0 0 0" axis="0 0 1" range="-1.61443 1.61443" actuatorfrcrange="-5 5" class="wrist_motor"/>
                          <geom type="mesh" contype="0" conaffinity="0" group="1" density="0" rgba="0.7 0.7 0.7 1" mesh="left_wrist_yaw_link"/>
                          <geom type="mesh" rgba="0.7 0.7 0.7 1" mesh="left_wrist_yaw_link"/>
                          <geom pos="0.0415 0 0" quat="3.17467e-11 0.707107 -3.17466e-11 0.707107" type="mesh" contype="0" conaffinity="0" group="1" density="0" rgba="0.792157 0.819608 0.933333 1" mesh="left_base_link"/>
                          <geom pos="0.0415 0 0" quat="3.17467e-11 0.707107 -3.17466e-11 0.707107" type="mesh" rgba="0.792157 0.819608 0.933333 1" mesh="left_base_link"/>
                          <geom pos="0.1611 -0.012296 0.00036819" quat="-0.499997 -0.500003 -0.500001 0.499999" type="mesh" contype="0" conaffinity="0" group="1" density="0" rgba="0.411765 0.411765 0.411765 1" mesh="left_palm_force_sensor"/>
                          <geom pos="0.1611 -0.012296 0.00036819" quat="-0.499997 -0.500003 -0.500001 0.499999" type="mesh" rgba="0.411765 0.411765 0.411765 1" mesh="left_palm_force_sensor"/>
                          <body name="left_thumb_1" pos="0.1104 -0.02101 0.0269" quat="3.17467e-11 0.707107 -3.17467e-11 0.707107">
                            <inertial pos="0.000892587 0.000344905 0.00159994" quat="0.985466 0.00605548 0.115048 0.124838" mass="0.00746" diaginertia="1.34891e-07 1.09691e-07 6.68155e-08"/>
                            <joint name="left_thumb_1_joint" pos="0 0 0" axis="0 0 1" range="0 1.1641" actuatorfrcrange="-10 10"/>
                            <geom type="mesh" contype="0" conaffinity="0" group="1" density="0" rgba="0.792157 0.819608 0.933333 1" mesh="left_thumb_1"/>
                            <geom type="mesh" rgba="0.792157 0.819608 0.933333 1" mesh="left_thumb_1"/>
                            <body name="left_thumb_2" pos="0.0073431 0.011232 0.0052" quat="0.0922934 0.0922938 -0.701059 -0.701056">
                              <inertial pos="-0.0141191 0.0118389 -0.0088672" quat="0.152261 0.678876 -0.168783 0.698181" mass="0.04364" diaginertia="1.52495e-06 1.17176e-06 1.06745e-06"/>
                              <joint name="left_thumb_2_joint" pos="0 0 0" axis="0 0 -1" range="0 0.5864" actuatorfrcrange="-10 10"/>
                              <geom type="mesh" contype="0" conaffinity="0" group="1" density="0" rgba="0.792157 0.819608 0.933333 1" mesh="left_thumb_2"/>
                              <geom type="mesh" rgba="0.792157 0.819608 0.933333 1" mesh="left_thumb_2"/>
                              <geom pos="-0.0087121 0.026305 -0.0089605" quat="0.405917 -0.578993 -0.405916 -0.578991" type="mesh" contype="0" conaffinity="0" group="1" density="0" rgba="0.411765 0.411765 0.411765 1" mesh="left_thumb_force_sensor_1"/>
                              <geom pos="-0.0087121 0.026305 -0.0089605" quat="0.405917 -0.578993 -0.405916 -0.578991" type="mesh" rgba="0.411765 0.411765 0.411765 1" mesh="left_thumb_force_sensor_1"/>
                              <body name="left_thumb_3" pos="-0.031403 0.021069 -0.001299">
                                <inertial pos="-0.0106831 0.00293204 -0.0079803" quat="0.630491 0.725992 0.273308 -0.0268299" mass="0.01601" diaginertia="1.03234e-06 9.80921e-07 4.62549e-07"/>
                                <joint name="left_thumb_3_joint" pos="0 0 0" axis="0 0 -1" range="0 0.5" actuatorfrcrange="-10 10"/>
                                <geom type="mesh" contype="0" conaffinity="0" group="1" density="0" rgba="0.792157 0.819608 0.933333 1" mesh="left_thumb_3"/>
                                <geom type="mesh" rgba="0.792157 0.819608 0.933333 1" mesh="left_thumb_3"/>
                                <geom pos="-0.011771 0.01699 -0.0077514" quat="0.428302 -0.562766 -0.428175 -0.562599" type="mesh" contype="0" conaffinity="0" group="1" density="0" rgba="0.411765 0.411765 0.411765 1" mesh="left_thumb_force_sensor_2"/>
                                <geom pos="-0.011771 0.01699 -0.0077514" quat="0.428302 -0.562766 -0.428175 -0.562599" type="mesh" rgba="0.411765 0.411765 0.411765 1" mesh="left_thumb_force_sensor_2"/>
                                <body name="left_thumb_4" pos="-0.021903 0.012816 -0.0003">
                                  <inertial pos="-0.0154206 0.00325953 -0.00981932" quat="0.509539 0.730741 0.454295 -0.00191329" mass="0.01172" diaginertia="2.01225e-06 1.78327e-06 7.11257e-07"/>
                                  <joint name="left_thumb_4_joint" pos="0 0 0" axis="0 0 -1" range="0 3.14" actuatorfrcrange="-10 10"/>
                                  <geom type="mesh" contype="0" conaffinity="0" group="1" density="0" rgba="0.792157 0.819608 0.933333 1" mesh="left_thumb_4"/>
                                  <geom type="mesh" rgba="0.792157 0.819608 0.933333 1" mesh="left_thumb_4"/>
                                  <geom pos="-0.014598 0.014721 -0.0073103" quat="0.348432 -0.615302 -0.348433 -0.615299" type="mesh" contype="0" conaffinity="0" group="1" density="0" rgba="0.411765 0.411765 0.411765 1" mesh="left_thumb_force_sensor_3"/>
                                  <geom pos="-0.014598 0.014721 -0.0073103" quat="0.348432 -0.615302 -0.348433 -0.615299" type="mesh" rgba="0.411765 0.411765 0.411765 1" mesh="left_thumb_force_sensor_3"/>
                                  <geom pos="-0.028987 0.017301 -0.0073513" quat="-0.356218 0.610827 -0.356216 -0.610827" type="mesh" contype="0" conaffinity="0" group="1" density="0" rgba="0.411765 0.411765 0.411765 1" mesh="left_thumb_force_sensor_4"/>
                                  <geom pos="-0.028987 0.017301 -0.0073513" quat="-0.356218 0.610827 -0.356216 -0.610827" type="mesh" rgba="0.411765 0.411765 0.411765 1" mesh="left_thumb_force_sensor_4"/>
                                </body>
                              </body>
                            </body>
                          </body>
                          <body name="left_index_1" pos="0.1979 -0.00056467 0.038679" quat="0.0123384 0.706999 0.706999 0.0123358">
                            <inertial pos="-0.0027798 0.0120616 0.00599425" quat="0.335314 0.231303 -0.81565 0.410827" mass="0.02941" diaginertia="2.19245e-06 1.8452e-06 8.88525e-07"/>
                            <joint name="left_index_1_joint" pos="0 0 0" axis="0 0 1" range="0 1.4381" actuatorfrcrange="-10 10"/>
                            <geom type="mesh" contype="0" conaffinity="0" group="1" density="0" rgba="0.792157 0.819608 0.933333 1" mesh="left_index_1"/>
                            <geom type="mesh" rgba="0.792157 0.819608 0.933333 1" mesh="left_index_1"/>
                            <geom pos="-0.012046 0.019649 0.006651" quat="0.701686 -0.0622873 -0.704358 -0.0873853" type="mesh" contype="0" conaffinity="0" group="1" density="0" rgba="0.411765 0.411765 0.411765 1" mesh="left_index_force_sensor_1"/>
                            <geom pos="-0.012046 0.019649 0.006651" quat="0.701686 -0.0622873 -0.704358 -0.0873853" type="mesh" rgba="0.411765 0.411765 0.411765 1" mesh="left_index_force_sensor_1"/>
                            <body name="left_index_2" pos="-0.0034259 0.032596 0.00055">
                              <inertial pos="-0.00156369 0.0175358 0.00500993" quat="0.396288 0.415196 -0.594023 0.563654" mass="0.01418" diaginertia="1.00912e-05 8.43434e-06 1.98804e-06"/>
                              <joint name="left_index_2_joint" pos="0 0 0" axis="0 0 1" range="0 3.14" actuatorfrcrange="-10 10"/>
                              <geom type="mesh" contype="0" conaffinity="0" group="1" density="0" rgba="0.792157 0.819608 0.933333 1" mesh="left_index_2"/>
                              <geom type="mesh" rgba="0.792157 0.819608 0.933333 1" mesh="left_index_2"/>
                              <geom pos="-0.0081655 0.037446 0.0060795" quat="0.698536 0.13559 -0.693985 0.109758" type="mesh" contype="0" conaffinity="0" group="1" density="0" rgba="0.411765 0.411765 0.411765 1" mesh="left_index_force_sensor_2"/>
                              <geom pos="-0.0081655 0.037446 0.0060795" quat="0.698536 0.13559 -0.693985 0.109758" type="mesh" rgba="0.411765 0.411765 0.411765 1" mesh="left_index_force_sensor_2"/>
                              <geom pos="-0.0086237 0.052572 0.0060954" quat="0.658743 -0.226725 -0.669773 -0.257017" type="mesh" contype="0" conaffinity="0" group="1" density="0" rgba="0.411765 0.411765 0.411765 1" mesh="left_index_force_sensor_3"/>
                              <geom pos="-0.0086237 0.052572 0.0060954" quat="0.658743 -0.226725 -0.669773 -0.257017" type="mesh" rgba="0.411765 0.411765 0.411765 1" mesh="left_index_force_sensor_3"/>
                            </body>
                          </body>
                          <body name="left_middle_1" pos="0.1985 -0.00056467 0.0171" quat="-3.35511e-11 0.707107 0.707107 -2.59738e-06">
                            <inertial pos="-0.00278814 0.0120854 0.00599425" quat="0.338048 0.229333 -0.817612 0.40576" mass="0.02941" diaginertia="2.17435e-06 1.81621e-06 8.99186e-07"/>
                            <joint name="left_middle_1_joint" pos="0 0 0" axis="0 0 1" range="0 1.4381" actuatorfrcrange="-10 10"/>
                            <geom type="mesh" contype="0" conaffinity="0" group="1" density="0" rgba="0.792157 0.819608 0.933333 1" mesh="left_middle_1"/>
                            <geom type="mesh" rgba="0.792157 0.819608 0.933333 1" mesh="left_middle_1"/>
                            <geom pos="-0.012046 0.019649 0.006651" quat="0.703134 -0.0748456 -0.703135 -0.0748437" type="mesh" contype="0" conaffinity="0" group="1" density="0" rgba="0.411765 0.411765 0.411765 1" mesh="left_middle_force_sensor_1"/>
                            <geom pos="-0.012046 0.019649 0.006651" quat="0.703134 -0.0748456 -0.703135 -0.0748437" type="mesh" rgba="0.411765 0.411765 0.411765 1" mesh="left_middle_force_sensor_1"/>
                            <body name="left_middle_2" pos="-0.0034259 0.032596 0.00055">
                              <inertial pos="-0.00206152 0.0203704 0.00493141" quat="0.402299 0.423075 -0.602547 0.544152" mass="0.01761" diaginertia="1.1944e-05 1.00683e-05 2.23451e-06"/>
                              <joint name="left_middle_2_joint" pos="0 0 0" axis="0 0 1" range="0 3.14" actuatorfrcrange="-10 10"/>
                              <geom type="mesh" contype="0" conaffinity="0" group="1" density="0" rgba="0.792157 0.819608 0.933333 1" mesh="left_middle_2"/>
                              <geom type="mesh" rgba="0.792157 0.819608 0.933333 1" mesh="left_middle_2"/>
                              <geom pos="-0.009086 0.040962 0.0061003" quat="0.694858 0.131041 -0.694858 0.131044" type="mesh" contype="0" conaffinity="0" group="1" density="0" rgba="0.411765 0.411765 0.411765 1" mesh="left_middle_force_sensor_2"/>
                              <geom pos="-0.009086 0.040962 0.0061003" quat="0.694858 0.131041 -0.694858 0.131044" type="mesh" rgba="0.411765 0.411765 0.411765 1" mesh="left_middle_force_sensor_2"/>
                              <geom pos="-0.0098294 0.056051 0.0061006" quat="0.667288 -0.233938 -0.667289 -0.233936" type="mesh" contype="0" conaffinity="0" group="1" density="0" rgba="0.411765 0.411765 0.411765 1" mesh="left_middle_force_sensor_3"/>
                              <geom pos="-0.0098294 0.056051 0.0061006" quat="0.667288 -0.233938 -0.667289 -0.233936" type="mesh" rgba="0.411765 0.411765 0.411765 1" mesh="left_middle_force_sensor_3"/>
                            </body>
                          </body>
                          <body name="left_ring_1" pos="0.19833 -0.00056467 -0.0045302" quat="-0.0185241 0.706864 0.706864 -0.0185267">
                            <inertial pos="-0.00279904 0.0121214 0.00599425" quat="0.341657 0.226163 -0.820695 0.398222" mass="0.02941" diaginertia="2.14701e-06 1.77247e-06 9.1533e-07"/>
                            <joint name="left_ring_1_joint" pos="0 0 0" axis="0 0 1" range="0 1.4381" actuatorfrcrange="-10 10"/>
                            <geom type="mesh" contype="0" conaffinity="0" group="1" density="0" rgba="0.792157 0.819608 0.933333 1" mesh="left_ring_1"/>
                            <geom type="mesh" rgba="0.792157 0.819608 0.933333 1" mesh="left_ring_1"/>
                            <geom pos="-0.012046 0.019649 0.006651" quat="0.704887 -0.0936618 -0.700876 -0.0559809" type="mesh" contype="0" conaffinity="0" group="1" density="0" rgba="0.411765 0.411765 0.411765 1" mesh="left_ring_force_sensor_1"/>
                            <geom pos="-0.012046 0.019649 0.006651" quat="0.704887 -0.0936618 -0.700876 -0.0559809" type="mesh" rgba="0.411765 0.411765 0.411765 1" mesh="left_ring_force_sensor_1"/>
                            <body name="left_ring_2" pos="-0.0034259 0.032596 0.00055">
                              <inertial pos="-0.00191784 0.0180594 0.00504847" quat="0.408379 0.398611 -0.604779 0.555499" mass="0.01481" diaginertia="1.00053e-05 8.41672e-06 1.9262e-06"/>
                              <joint name="left_ring_2_joint" pos="0 0 0" axis="0 0 1" range="0 3.14" actuatorfrcrange="-10 10"/>
                              <geom type="mesh" contype="0" conaffinity="0" group="1" density="0" rgba="0.792157 0.819608 0.933333 1" mesh="left_ring_2"/>
                              <geom type="mesh" rgba="0.792157 0.819608 0.933333 1" mesh="left_ring_2"/>
                              <geom pos="-0.0081655 0.037446 0.0060795" quat="0.692694 0.103257 -0.699527 0.142038" type="mesh" contype="0" conaffinity="0" group="1" density="0" rgba="0.411765 0.411765 0.411765 1" mesh="left_ring_force_sensor_2"/>
                              <geom pos="-0.0081655 0.037446 0.0060795" quat="0.692694 0.103257 -0.699527 0.142038" type="mesh" rgba="0.411765 0.411765 0.411765 1" mesh="left_ring_force_sensor_2"/>
                              <geom pos="-0.0086237 0.052572 0.0060954" quat="0.6723 -0.264487 -0.655779 -0.219118" type="mesh" contype="0" conaffinity="0" group="1" density="0" rgba="0.411765 0.411765 0.411765 1" mesh="left_ring_force_sensor_3"/>
                              <geom pos="-0.0086237 0.052572 0.0060954" quat="0.6723 -0.264487 -0.655779 -0.219118" type="mesh" rgba="0.411765 0.411765 0.411765 1" mesh="left_ring_force_sensor_3"/>
                            </body>
                          </body>
                          <body name="left_little_1" pos="0.19515 -0.00056467 -0.025916" quat="-0.0370001 0.706138 0.706138 -0.0370027">
                            <inertial pos="-0.00280799 0.012158 0.00599425" quat="0.34468 0.222753 -0.823943 0.390763" mass="0.02941" diaginertia="2.11947e-06 1.72847e-06 9.31639e-07"/>
                            <joint name="left_little_1_joint" pos="0 0 0" axis="0 0 1" range="0 1.4381" actuatorfrcrange="-10 10"/>
                            <geom type="mesh" contype="0" conaffinity="0" group="1" density="0" rgba="0.792157 0.819608 0.933333 1" mesh="left_little_1"/>
                            <geom type="mesh" rgba="0.792157 0.819608 0.933333 1" mesh="left_little_1"/>
                            <geom pos="-0.012046 0.019649 0.006651" quat="0.706132 -0.112374 -0.69812 -0.0371073" type="mesh" contype="0" conaffinity="0" group="1" density="0" rgba="0.411765 0.411765 0.411765 1" mesh="left_little_force_sensor_1"/>
                            <geom pos="-0.012046 0.019649 0.006651" quat="0.706132 -0.112374 -0.69812 -0.0371073" type="mesh" rgba="0.411765 0.411765 0.411765 1" mesh="left_little_force_sensor_1"/>
                            <body name="left_little_2" pos="-0.0034259 0.032596 0.00055">
                              <inertial pos="-0.00124753 0.0130025 0.00463411" quat="0.400355 0.386309 -0.630274 0.541512" mass="0.01157" diaginertia="6.18511e-06 5.27433e-06 1.16308e-06"/>
                              <joint name="left_little_2_joint" pos="0 0 0" axis="0 0 1" range="0 3.14" actuatorfrcrange="-10 10"/>
                              <geom type="mesh" contype="0" conaffinity="0" group="1" density="0" rgba="0.792157 0.819608 0.933333 1" mesh="left_little_2"/>
                              <geom type="mesh" rgba="0.792157 0.819608 0.933333 1" mesh="left_little_2"/>
                              <geom pos="-0.0064514 0.027683 0.0061172" quat="0.689046 0.0814204 -0.702404 0.158792" type="mesh" contype="0" conaffinity="0" group="1" density="0" rgba="0.411765 0.411765 0.411765 1" mesh="left_little_force_sensor_2"/>
                              <geom pos="-0.0064514 0.027683 0.0061172" quat="0.689046 0.0814204 -0.702404 0.158792" type="mesh" rgba="0.411765 0.411765 0.411765 1" mesh="left_little_force_sensor_2"/>
                              <geom pos="-0.0063973 0.042707 0.0061154" quat="0.678772 -0.289133 -0.645293 -0.198161" type="mesh" contype="0" conaffinity="0" group="1" density="0" rgba="0.411765 0.411765 0.411765 1" mesh="left_little_force_sensor_3"/>
                              <geom pos="-0.0063973 0.042707 0.0061154" quat="0.678772 -0.289133 -0.645293 -0.198161" type="mesh" rgba="0.411765 0.411765 0.411765 1" mesh="left_little_force_sensor_3"/>
                            </body>
                          </body>
                        </body>
                      </body>
                    </body>
                  </body>
                </body>
              </body>
            </body>
            <body name="right_shoulder_pitch_link" pos="0.0039563 -0.10021 0.24778" quat="0.990264 -0.139201 1.38722e-05 9.86868e-05">
              <inertial pos="0 -0.035892 -0.011628" quat="0.68225 -0.326267 0.0130458 0.654152" mass="0.718" diaginertia="0.000465864 0.000432842 0.000406394"/>
              <joint name="right_shoulder_pitch_joint" pos="0 0 0" axis="0 1 0" range="-3.0892 2.6704" actuatorfrcrange="-25 25" class="arm_motor"/>
              <geom type="mesh" contype="0" conaffinity="0" group="1" density="0" rgba="0.7 0.7 0.7 1" mesh="right_shoulder_pitch_link"/>
              <geom size="0.03 0.025" pos="0 -0.04 -0.01" quat="0.707107 0 0.707107 0" type="cylinder" rgba="0.7 0.7 0.7 1"/>
              <body name="right_shoulder_roll_link" pos="0 -0.038 -0.013831" quat="0.990268 0.139172 0 0">
                <inertial pos="-0.000227 -0.00727 -0.063243" quat="0.712604 -0.00710317 -0.0196223 0.701256" mass="0.643" diaginertia="0.000691311 0.000618011 0.000388977"/>
                <joint name="right_shoulder_roll_joint" pos="0 0 0" axis="1 0 0" range="-2.2515 1.5882" actuatorfrcrange="-25 25" class="arm_motor"/>
                <geom type="mesh" contype="0" conaffinity="0" group="1" density="0" rgba="0.7 0.7 0.7 1" mesh="right_shoulder_roll_link"/>
                <geom size="0.03 0.015" pos="-0.004 -0.006 -0.053" type="cylinder" rgba="0.7 0.7 0.7 1"/>
                <body name="right_shoulder_yaw_link" pos="0 -0.00624 -0.1032">
                  <inertial pos="0.010773 0.002949 -0.072009" quat="0.687134 -0.0679942 -0.0964829 0.716879" mass="0.734" diaginertia="0.00106187 0.00103217 0.000400661"/>
                  <joint name="right_shoulder_yaw_joint" pos="0 0 0" axis="0 0 1" range="-2.618 2.618" actuatorfrcrange="-25 25" class="arm_motor"/>
                  <geom type="mesh" contype="0" conaffinity="0" group="1" density="0" rgba="0.7 0.7 0.7 1" mesh="right_shoulder_yaw_link"/>
                  <geom type="mesh" rgba="0.7 0.7 0.7 1" mesh="right_shoulder_yaw_link"/>
                  <body name="right_elbow_link" pos="0.015783 0 -0.080518">
                    <inertial pos="0.064956 -0.004454 -0.010062" quat="0.388129 0.388821 0.636132 0.541765" mass="0.6" diaginertia="0.000443035 0.000421612 0.000259353"/>
                    <joint name="right_elbow_joint" pos="0 0 0" axis="0 1 0" range="-1.0472 2.0944" actuatorfrcrange="-25 25" class="arm_motor"/>
                    <geom type="mesh" contype="0" conaffinity="0" group="1" density="0" rgba="0.7 0.7 0.7 1" mesh="right_elbow_link"/>
                    <geom type="mesh" rgba="0.7 0.7 0.7 1" mesh="right_elbow_link"/>
                    <body name="right_wrist_roll_link" pos="0.1 -0.00188791 -0.01">
                      <inertial pos="0.0171394 -0.000537591 4.8864e-07" quat="0.411667 0.575338 -0.411094 0.574906" mass="0.085445" diaginertia="5.48211e-05 4.96646e-05 3.57798e-05"/>
                      <joint name="right_wrist_roll_joint" pos="0 0 0" axis="1 0 0" range="-1.97222 1.97222" actuatorfrcrange="-25 25" class="arm_motor"/>
                      <geom type="mesh" contype="0" conaffinity="0" group="1" density="0" rgba="0.7 0.7 0.7 1" mesh="right_wrist_roll_link"/>
                      <geom type="mesh" rgba="0.7 0.7 0.7 1" mesh="right_wrist_roll_link"/>
                      <body name="right_wrist_pitch_link" pos="0.038 0 0">
                        <inertial pos="0.0229999 0.00111685 -0.00111658" quat="0.643608 0.293036 0.661363 0.249998" mass="0.48405" diaginertia="0.000430353 0.000429873 0.000164648"/>
                        <joint name="right_wrist_pitch_joint" pos="0 0 0" axis="0 1 0" range="-1.61443 1.61443" actuatorfrcrange="-5 5" class="wrist_motor"/>
                        <geom type="mesh" contype="0" conaffinity="0" group="1" density="0" rgba="0.7 0.7 0.7 1" mesh="right_wrist_pitch_link"/>
                        <geom type="mesh" rgba="0.7 0.7 0.7 1" mesh="right_wrist_pitch_link"/>
                        <body name="right_wrist_yaw_link" pos="0.046 0 0">
                          <inertial pos="0.00180234 0.0334078 0.0680974" quat="0.834753 -0.210685 -0.0151004 0.5085" mass="0.708236" diaginertia="0.000907937 0.000874537 0.000236995"/>
                          <joint name="right_wrist_yaw_joint" pos="0 0 0" axis="0 0 1" range="-1.61443 1.61443" actuatorfrcrange="-5 5" class="wrist_motor"/>
                          <geom type="mesh" contype="0" conaffinity="0" group="1" density="0" rgba="0.7 0.7 0.7 1" mesh="right_wrist_yaw_link"/>
                          <geom type="mesh" rgba="0.7 0.7 0.7 1" mesh="right_wrist_yaw_link"/>
                          <geom pos="0.0415 0 0" quat="0.707107 0 0.707107 0" type="mesh" contype="0" conaffinity="0" group="1" density="0" rgba="1 1 1 1" mesh="right_base_link"/>
                          <geom pos="0.0415 0 0" quat="0.707107 0 0.707107 0" type="mesh" rgba="1 1 1 1" mesh="right_base_link"/>
                          <geom pos="0.1611 0.012296 0.00036819" quat="0.499999 -0.500001 -0.500003 -0.499997" type="mesh" contype="0" conaffinity="0" group="1" density="0" rgba="0.411765 0.411765 0.411765 1" mesh="right_palm_force_sensor"/>
                          <geom pos="0.1611 0.012296 0.00036819" quat="0.499999 -0.500001 -0.500003 -0.499997" type="mesh" rgba="0.411765 0.411765 0.411765 1" mesh="right_palm_force_sensor"/>
                          <body name="right_thumb_1" pos="0.1104 0.02101 0.0269" quat="0.707107 0 0.707107 0">
                            <inertial pos="-0.000892587 0.000344906 0.00159994" quat="0.985466 0.0060554 -0.115048 -0.124838" mass="0.00746" diaginertia="1.34891e-07 1.09691e-07 6.68155e-08"/>
                            <joint name="right_thumb_1_joint" pos="0 0 0" axis="0 0 -1" range="0 1.1641" actuatorfrcrange="-10 10"/>
                            <geom type="mesh" contype="0" conaffinity="0" group="1" density="0" rgba="1 1 1 1" mesh="right_thumb_1"/>
                            <geom type="mesh" rgba="1 1 1 1" mesh="right_thumb_1"/>
                            <body name="right_thumb_2" pos="-0.0079252 0.0090599 0.0052" quat="0.0922934 0.0922938 0.701059 0.701056">
                              <inertial pos="0.0129116 0.0117966 -0.00627818" quat="-0.0815936 0.801441 0.0320301 0.591615" mass="0.04364" diaginertia="3.13605e-06 2.81925e-06 1.0836e-06"/>
                              <joint name="right_thumb_2_joint" pos="0 0 0" axis="0 0 1" range="0 0.5864" actuatorfrcrange="-10 10"/>
                              <geom type="mesh" contype="0" conaffinity="0" group="1" density="0" rgba="1 1 1 1" mesh="right_thumb_2"/>
                              <geom type="mesh" rgba="1 1 1 1" mesh="right_thumb_2"/>
                              <geom pos="0.0087121 0.026305 -0.0067115" quat="0.579327 -0.405437 -0.579328 -0.405439" type="mesh" contype="0" conaffinity="0" group="1" density="0" rgba="0.411765 0.411765 0.411765 1" mesh="right_thumb_force_sensor_1"/>
                              <geom pos="0.0087121 0.026305 -0.0067115" quat="0.579327 -0.405437 -0.579328 -0.405439" type="mesh" rgba="0.411765 0.411765 0.411765 1" mesh="right_thumb_force_sensor_1"/>
                              <body name="right_thumb_3" pos="0.031403 0.021069 0.00095">
                                <inertial pos="0.00971763 0.00293901 -0.00649715" quat="0.807724 0.467335 -0.172304 -0.315423" mass="0.01601" diaginertia="1.67363e-06 1.56118e-06 4.45271e-07"/>
                                <joint name="right_thumb_3_joint" pos="0 0 0" axis="0 0 1" range="0 0.5" actuatorfrcrange="-10 10"/>
                                <geom type="mesh" contype="0" conaffinity="0" group="1" density="0" rgba="1 1 1 1" mesh="right_thumb_3"/>
                                <geom type="mesh" rgba="1 1 1 1" mesh="right_thumb_3"/>
                                <geom pos="0.011771 0.01699 -0.0077514" quat="-0.562601 0.428173 0.562767 0.4283" type="mesh" contype="0" conaffinity="0" group="1" density="0" rgba="0.411765 0.411765 0.411765 1" mesh="right_thumb_force_sensor_2"/>
                                <geom pos="0.011771 0.01699 -0.0077514" quat="-0.562601 0.428173 0.562767 0.4283" type="mesh" rgba="0.411765 0.411765 0.411765 1" mesh="right_thumb_force_sensor_2"/>
                                <body name="right_thumb_4" pos="0.021903 0.012816 -0.0003">
                                  <inertial pos="0.0116518 0.00327246 -0.00268043" quat="-0.0664901 0.845795 0.311379 0.428081" mass="0.01172" diaginertia="3.86055e-06 3.73237e-06 1.02914e-06"/>
                                  <joint name="right_thumb_4_joint" pos="0 0 0" axis="0 0 1" range="0 3.14" actuatorfrcrange="-10 10"/>
                                  <geom type="mesh" contype="0" conaffinity="0" group="1" density="0" rgba="1 1 1 1" mesh="right_thumb_4"/>
                                  <geom type="mesh" rgba="1 1 1 1" mesh="right_thumb_4"/>
                                  <geom pos="0.014598 0.01472 -0.0073103" quat="0.615658 -0.347798 -0.615661 -0.347797" type="mesh" contype="0" conaffinity="0" group="1" density="0" rgba="0.411765 0.411765 0.411765 1" mesh="right_thumb_force_sensor_3"/>
                                  <geom pos="0.014598 0.01472 -0.0073103" quat="0.615658 -0.347798 -0.615661 -0.347797" type="mesh" rgba="0.411765 0.411765 0.411765 1" mesh="right_thumb_force_sensor_3"/>
                                  <geom pos="0.028987 0.017301 -0.0073512" quat="0.609148 -0.359083 0.609147 0.359081" type="mesh" contype="0" conaffinity="0" group="1" density="0" rgba="0.411765 0.411765 0.411765 1" mesh="right_thumb_force_sensor_4"/>
                                  <geom pos="0.028987 0.017301 -0.0073512" quat="0.609148 -0.359083 0.609147 0.359081" type="mesh" rgba="0.411765 0.411765 0.411765 1" mesh="right_thumb_force_sensor_4"/>
                                </body>
                              </body>
                            </body>
                          </body>
                          <body name="right_index_1" pos="0.1979 0.00056467 0.038679" quat="0.706999 0.0123384 -0.012341 -0.706999">
                            <inertial pos="-0.00277903 0.0125621 -0.00685183" quat="0.426981 0.417168 -0.595771 0.537322" mass="0.02941" diaginertia="1.52353e-06 1.16766e-06 8.69688e-07"/>
                            <joint name="right_index_1_joint" pos="0 0 0" axis="0 0 1" range="0 1.4381" actuatorfrcrange="-10 10"/>
                            <geom type="mesh" contype="0" conaffinity="0" group="1" density="0" rgba="1 1 1 1" mesh="right_index_1"/>
                            <geom type="mesh" rgba="1 1 1 1" mesh="right_index_1"/>
                            <geom pos="-0.012046 0.019649 -0.006651" quat="0.704358 -0.0873853 -0.701686 -0.0622873" type="mesh" contype="0" conaffinity="0" group="1" density="0" rgba="0.411765 0.411765 0.411765 1" mesh="right_index_force_sensor_1"/>
                            <geom pos="-0.012046 0.019649 -0.006651" quat="0.704358 -0.0873853 -0.701686 -0.0622873" type="mesh" rgba="0.411765 0.411765 0.411765 1" mesh="right_index_force_sensor_1"/>
                            <body name="right_index_2" pos="-0.0034259 0.032596 -0.00055">
                              <inertial pos="-0.00276726 0.018588 -0.00545137" quat="0.530279 0.423867 -0.516746 0.521646" mass="0.01418" diaginertia="9.37095e-06 8.09391e-06 1.70538e-06"/>
                              <joint name="right_index_2_joint" pos="0 0 0" axis="0 0 1" range="0 3.14" actuatorfrcrange="-10 10"/>
                              <geom type="mesh" contype="0" conaffinity="0" group="1" density="0" rgba="1 1 1 1" mesh="right_index_2"/>
                              <geom type="mesh" rgba="1 1 1 1" mesh="right_index_2"/>
                              <geom pos="-0.0081655 0.037446 -0.0060795" quat="0.693985 0.109758 -0.698536 0.13559" type="mesh" contype="0" conaffinity="0" group="1" density="0" rgba="0.411765 0.411765 0.411765 1" mesh="right_index_force_sensor_2"/>
                              <geom pos="-0.0081655 0.037446 -0.0060795" quat="0.693985 0.109758 -0.698536 0.13559" type="mesh" rgba="0.411765 0.411765 0.411765 1" mesh="right_index_force_sensor_2"/>
                              <geom pos="-0.0086237 0.052572 -0.0060954" quat="0.66977 -0.257027 -0.658739 -0.226735" type="mesh" contype="0" conaffinity="0" group="1" density="0" rgba="0.411765 0.411765 0.411765 1" mesh="right_index_force_sensor_3"/>
                              <geom pos="-0.0086237 0.052572 -0.0060954" quat="0.66977 -0.257027 -0.658739 -0.226735" type="mesh" rgba="0.411765 0.411765 0.411765 1" mesh="right_index_force_sensor_3"/>
                            </body>
                          </body>
                          <body name="right_middle_1" pos="0.1985 0.00056467 0.0171" quat="0.707107 3.3551e-11 -2.59738e-06 -0.707107">
                            <inertial pos="-0.00278766 0.0125385 -0.00685183" quat="0.437494 0.408757 -0.606551 0.52308" mass="0.02941" diaginertia="1.53966e-06 1.17768e-06 8.75576e-07"/>
                            <joint name="right_middle_1_joint" pos="0 0 0" axis="0 0 1" range="0 1.4381" actuatorfrcrange="-10 10"/>
                            <geom type="mesh" contype="0" conaffinity="0" group="1" density="0" rgba="1 1 1 1" mesh="right_middle_1"/>
                            <geom type="mesh" rgba="1 1 1 1" mesh="right_middle_1"/>
                            <geom pos="-0.012046 0.019649 -0.006651" quat="-0.703076 0.0754056 0.703073 0.0754054" type="mesh" contype="0" conaffinity="0" group="1" density="0" rgba="0.411765 0.411765 0.411765 1" mesh="right_middle_force_sensor_1"/>
                            <geom pos="-0.012046 0.019649 -0.006651" quat="-0.703076 0.0754056 0.703073 0.0754054" type="mesh" rgba="0.411765 0.411765 0.411765 1" mesh="right_middle_force_sensor_1"/>
                            <body name="right_middle_2" pos="-0.0034259 0.032596 -0.00055">
                              <inertial pos="-0.00275426 0.0210621 -0.0058845" quat="0.508601 0.438771 -0.528202 0.51943" mass="0.01761" diaginertia="1.11711e-05 9.60259e-06 1.98242e-06"/>
                              <joint name="right_middle_2_joint" pos="0 0 0" axis="0 0 1" range="0 3.14" actuatorfrcrange="-10 10"/>
                              <geom type="mesh" contype="0" conaffinity="0" group="1" density="0" rgba="1 1 1 1" mesh="right_middle_2"/>
                              <geom type="mesh" rgba="1 1 1 1" mesh="right_middle_2"/>
                              <geom pos="-0.0090859 0.040963 -0.0061003" quat="-0.695008 -0.130248 0.695006 -0.130249" type="mesh" contype="0" conaffinity="0" group="1" density="0" rgba="0.411765 0.411765 0.411765 1" mesh="right_middle_force_sensor_2"/>
                              <geom pos="-0.0090859 0.040963 -0.0061003" quat="-0.695008 -0.130248 0.695006 -0.130249" type="mesh" rgba="0.411765 0.411765 0.411765 1" mesh="right_middle_force_sensor_2"/>
                              <geom pos="-0.0098294 0.056051 -0.0061006" quat="-0.667101 0.234473 0.667099 0.234472" type="mesh" contype="0" conaffinity="0" group="1" density="0" rgba="0.411765 0.411765 0.411765 1" mesh="right_middle_force_sensor_3"/>
                              <geom pos="-0.0098294 0.056051 -0.0061006" quat="-0.667101 0.234473 0.667099 0.234472" type="mesh" rgba="0.411765 0.411765 0.411765 1" mesh="right_middle_force_sensor_3"/>
                            </body>
                          </body>
                          <body name="right_ring_1" pos="0.19833 0.00056467 -0.0045302" quat="0.706864 -0.0185241 0.0185215 -0.706864">
                            <inertial pos="-0.00279907 0.0125023 -0.00685183" quat="0.452184 0.396123 -0.621547 0.50229" mass="0.02941" diaginertia="1.56456e-06 1.19708e-06 8.80797e-07"/>
                            <joint name="right_ring_1_joint" pos="0 0 0" axis="0 0 1" range="0 1.4381" actuatorfrcrange="-10 10"/>
                            <geom type="mesh" contype="0" conaffinity="0" group="1" density="0" rgba="1 1 1 1" mesh="right_ring_1"/>
                            <geom type="mesh" rgba="1 1 1 1" mesh="right_ring_1"/>
                            <geom pos="-0.0120462 0.0196485 -0.00665098" quat="0.700879 -0.0559904 -0.704887 -0.0936441" type="mesh" contype="0" conaffinity="0" group="1" density="0" rgba="0.411765 0.411765 0.411765 1" mesh="right_ring_force_sensor_1"/>
                            <geom pos="-0.0120462 0.0196485 -0.00665098" quat="0.700879 -0.0559904 -0.704887 -0.0936441" type="mesh" rgba="0.411765 0.411765 0.411765 1" mesh="right_ring_force_sensor_1"/>
                            <body name="right_ring_2" pos="-0.0034259 0.032596 -0.00055">
                              <inertial pos="-0.00225508 0.0185969 -0.00548621" quat="0.512134 0.432591 -0.5111 0.537923" mass="0.01481" diaginertia="9.58943e-06 8.24493e-06 1.76555e-06"/>
                              <joint name="right_ring_2_joint" pos="0 0 0" axis="0 0 1" range="0 3.14" actuatorfrcrange="-10 10"/>
                              <geom type="mesh" contype="0" conaffinity="0" group="1" density="0" rgba="1 1 1 1" mesh="right_ring_2"/>
                              <geom type="mesh" rgba="1 1 1 1" mesh="right_ring_2"/>
                              <geom pos="-0.00816549 0.0374458 -0.00607949" quat="0.699529 0.14203 -0.692696 0.103242" type="mesh" contype="0" conaffinity="0" group="1" density="0" rgba="0.411765 0.411765 0.411765 1" mesh="right_ring_force_sensor_2"/>
                              <geom pos="-0.00816549 0.0374458 -0.00607949" quat="0.699529 0.14203 -0.692696 0.103242" type="mesh" rgba="0.411765 0.411765 0.411765 1" mesh="right_ring_force_sensor_2"/>
                              <geom pos="-0.00862373 0.0525719 -0.00609539" quat="0.655775 -0.219109 -0.672303 -0.264497" type="mesh" contype="0" conaffinity="0" group="1" density="0" rgba="0.411765 0.411765 0.411765 1" mesh="right_ring_force_sensor_3"/>
                              <geom pos="-0.00862373 0.0525719 -0.00609539" quat="0.655775 -0.219109 -0.672303 -0.264497" type="mesh" rgba="0.411765 0.411765 0.411765 1" mesh="right_ring_force_sensor_3"/>
                            </body>
                          </body>
                          <body name="right_little_1" pos="0.19515 0.00056467 -0.025916" quat="0.706138 -0.0370001 0.0369975 -0.706138">
                            <inertial pos="-0.00280852 0.0124657 -0.00685182" quat="0.464726 0.384634 -0.63412 0.483713" mass="0.02941" diaginertia="1.59002e-06 1.22122e-06 8.81891e-07"/>
                            <joint name="right_little_1_joint" pos="0 0 0" axis="0 0 1" range="0 1.4381" actuatorfrcrange="-10 10"/>
                            <geom type="mesh" contype="0" conaffinity="0" group="1" density="0" rgba="1 1 1 1" mesh="right_little_1"/>
                            <geom type="mesh" rgba="1 1 1 1" mesh="right_little_1"/>
                            <geom pos="-0.0120462 0.0196485 -0.00665098" quat="0.698121 -0.0371013 -0.706133 -0.112372" type="mesh" contype="0" conaffinity="0" group="1" density="0" rgba="0.411765 0.411765 0.411765 1" mesh="right_little_force_sensor_1"/>
                            <geom pos="-0.0120462 0.0196485 -0.00665098" quat="0.698121 -0.0371013 -0.706133 -0.112372" type="mesh" rgba="0.411765 0.411765 0.411765 1" mesh="right_little_force_sensor_1"/>
                            <body name="right_little_2" pos="-0.0034259 0.032596 -0.00055">
                              <inertial pos="-0.00126052 0.0135222 -0.00546358" quat="0.514505 0.444248 -0.503136 0.53365" mass="0.01157" diaginertia="5.90249e-06 5.12172e-06 1.07769e-06"/>
                              <joint name="right_little_2_joint" pos="0 0 0" axis="0 0 1" range="0 3.14" actuatorfrcrange="-10 10"/>
                              <geom type="mesh" contype="0" conaffinity="0" group="1" density="0" rgba="1 1 1 1" mesh="right_little_2"/>
                              <geom type="mesh" rgba="1 1 1 1" mesh="right_little_2"/>
                              <geom pos="-0.00645124 0.0276833 -0.00611719" quat="0.702403 0.158797 -0.689045 0.0814212" type="mesh" contype="0" conaffinity="0" group="1" density="0" rgba="0.411765 0.411765 0.411765 1" mesh="right_little_force_sensor_2"/>
                              <geom pos="-0.00645124 0.0276833 -0.00611719" quat="0.702403 0.158797 -0.689045 0.0814212" type="mesh" rgba="0.411765 0.411765 0.411765 1" mesh="right_little_force_sensor_2"/>
                              <geom pos="-0.00639723 0.0427069 -0.00611537" quat="0.645296 -0.19817 -0.67877 -0.289124" type="mesh" contype="0" conaffinity="0" group="1" density="0" rgba="0.411765 0.411765 0.411765 1" mesh="right_little_force_sensor_3"/>
                              <geom pos="-0.00639723 0.0427069 -0.00611537" quat="0.645296 -0.19817 -0.67877 -0.289124" type="mesh" rgba="0.411765 0.411765 0.411765 1" mesh="right_little_force_sensor_3"/>
                            </body>
                          </body>
                        </body>
                      </body>
                    </body>
                  </body>
                </body>
              </body>
            </body>
          </body>
        </body>
      </body>
    </body>
  </worldbody>
  
  <actuator>
    <motor name="left_hip_pitch_joint_motor" joint="left_hip_pitch_joint" ctrlrange="-88 88" />
    <motor name="left_hip_roll_joint_motor" joint="left_hip_roll_joint" ctrlrange="-139 139" />
    <motor name="left_hip_yaw_joint_motor" joint="left_hip_yaw_joint" ctrlrange="-88 88" />
    <motor name="left_knee_joint_motor" joint="left_knee_joint" ctrlrange="-139 139" />
    <motor name="left_ankle_pitch_joint_motor" joint="left_ankle_pitch_joint" ctrlrange="-35 35" />
    <motor name="left_ankle_roll_joint_motor" joint="left_ankle_roll_joint" ctrlrange="-35 35" />
    <motor name="right_hip_pitch_joint_motor" joint="right_hip_pitch_joint" ctrlrange="-88 88" />
    <motor name="right_hip_roll_joint_motor" joint="right_hip_roll_joint" ctrlrange="-139 139" />
    <motor name="right_hip_yaw_joint_motor" joint="right_hip_yaw_joint" ctrlrange="-88 88" />
    <motor name="right_knee_joint_motor" joint="right_knee_joint" ctrlrange="-139 139" />
    <motor name="right_ankle_pitch_joint_motor" joint="right_ankle_pitch_joint" ctrlrange="-35 35" />
    <motor name="right_ankle_roll_joint_motor" joint="right_ankle_roll_joint" ctrlrange="-35 35" />
    <motor name="waist_yaw_joint_motor" joint="waist_yaw_joint" ctrlrange="-88 88" />
    <motor name="waist_roll_joint_motor" joint="waist_roll_joint" ctrlrange="-35 35" />
    <motor name="waist_pitch_joint_motor" joint="waist_pitch_joint" ctrlrange="-35 35" />
    <motor name="left_shoulder_pitch_joint_motor" joint="left_shoulder_pitch_joint" ctrlrange="-25 25" />
    <motor name="left_shoulder_roll_joint_motor" joint="left_shoulder_roll_joint" ctrlrange="-25 25" />
    <motor name="left_shoulder_yaw_joint_motor" joint="left_shoulder_yaw_joint" ctrlrange="-25 25" />
    <motor name="left_elbow_joint_motor" joint="left_elbow_joint" ctrlrange="-25 25" />
    <motor name="left_wrist_roll_joint_motor" joint="left_wrist_roll_joint" ctrlrange="-25 25" />
    <motor name="left_wrist_pitch_joint_motor" joint="left_wrist_pitch_joint" ctrlrange="-5 5" />
    <motor name="left_wrist_yaw_joint_motor" joint="left_wrist_yaw_joint" ctrlrange="-5 5" />
    <motor name="left_thumb_1_joint_motor" joint="left_thumb_1_joint" ctrlrange="-0.2 0.2" />
    <motor name="left_thumb_2_joint_motor" joint="left_thumb_2_joint" ctrlrange="-0.2 0.2" />
    <motor name="left_thumb_3_joint_motor" joint="left_thumb_3_joint" ctrlrange="-0.2 0.2" />
    <motor name="left_thumb_4_joint_motor" joint="left_thumb_4_joint" ctrlrange="-0.2 0.2" />
    <motor name="left_index_1_joint_motor" joint="left_index_1_joint" ctrlrange="-0.2 0.2" />
    <motor name="left_index_2_joint_motor" joint="left_index_2_joint" ctrlrange="-0.2 0.2" />
    <motor name="left_middle_1_joint_motor" joint="left_middle_1_joint" ctrlrange="-0.2 0.2" />
    <motor name="left_middle_2_joint_motor" joint="left_middle_2_joint" ctrlrange="-0.2 0.2" />
    <motor name="left_ring_1_joint_motor" joint="left_ring_1_joint" ctrlrange="-0.2 0.2" />
    <motor name="left_ring_2_joint_motor" joint="left_ring_2_joint" ctrlrange="-0.2 0.2" />
    <motor name="left_little_1_joint_motor" joint="left_little_1_joint" ctrlrange="-0.2 0.2" />
    <motor name="left_little_2_joint_motor" joint="left_little_2_joint" ctrlrange="-0.2 0.2" />
    <motor name="right_shoulder_pitch_joint_motor" joint="right_shoulder_pitch_joint" ctrlrange="-25 25" />
    <motor name="right_shoulder_roll_joint_motor" joint="right_shoulder_roll_joint" ctrlrange="-25 25" />
    <motor name="right_shoulder_yaw_joint_motor" joint="right_shoulder_yaw_joint" ctrlrange="-25 25" />
    <motor name="right_elbow_joint_motor" joint="right_elbow_joint" ctrlrange="-25 25" />
    <motor name="right_wrist_roll_joint_motor" joint="right_wrist_roll_joint" ctrlrange="-25 25" />
    <motor name="right_wrist_pitch_joint_motor" joint="right_wrist_pitch_joint" ctrlrange="-5 5" />
    <motor name="right_wrist_yaw_joint_motor" joint="right_wrist_yaw_joint" ctrlrange="-5 5" />
    <motor name="right_thumb_1_joint_motor" joint="right_thumb_1_joint" ctrlrange="-0.2 0.2" />
    <motor name="right_thumb_2_joint_motor" joint="right_thumb_2_joint" ctrlrange="-0.2 0.2" />
    <motor name="right_thumb_3_joint_motor" joint="right_thumb_3_joint" ctrlrange="-0.2 0.2" />
    <motor name="right_thumb_4_joint_motor" joint="right_thumb_4_joint" ctrlrange="-0.2 0.2" />
    <motor name="right_index_1_joint_motor" joint="right_index_1_joint" ctrlrange="-0.2 0.2" />
    <motor name="right_index_2_joint_motor" joint="right_index_2_joint" ctrlrange="-0.2 0.2" />
    <motor name="right_middle_1_joint_motor" joint="right_middle_1_joint" ctrlrange="-0.2 0.2" />
    <motor name="right_middle_2_joint_motor" joint="right_middle_2_joint" ctrlrange="-0.2 0.2" />
    <motor name="right_ring_1_joint_motor" joint="right_ring_1_joint" ctrlrange="-0.2 0.2" />
    <motor name="right_ring_2_joint_motor" joint="right_ring_2_joint" ctrlrange="-0.2 0.2" />
    <motor name="right_little_1_joint_motor" joint="right_little_1_joint" ctrlrange="-0.2 0.2" />
    <motor name="right_little_2_joint_motor" joint="right_little_2_joint" ctrlrange="-0.2 0.2" />
  </actuator>

  <sensor>
    <jointpos name="left_hip_pitch_joint_pos" joint="left_hip_pitch_joint" />
    <jointpos name="left_hip_roll_joint_pos" joint="left_hip_roll_joint" />
    <jointpos name="left_hip_yaw_joint_pos" joint="left_hip_yaw_joint" />
    <jointpos name="left_knee_joint_pos" joint="left_knee_joint" />
    <jointpos name="left_ankle_pitch_joint_pos" joint="left_ankle_pitch_joint" />
    <jointpos name="left_ankle_roll_joint_pos" joint="left_ankle_roll_joint" />
    <jointpos name="right_hip_pitch_joint_pos" joint="right_hip_pitch_joint" />
    <jointpos name="right_hip_roll_joint_pos" joint="right_hip_roll_joint" />
    <jointpos name="right_hip_yaw_joint_pos" joint="right_hip_yaw_joint" />
    <jointpos name="right_knee_joint_pos" joint="right_knee_joint" />
    <jointpos name="right_ankle_pitch_joint_pos" joint="right_ankle_pitch_joint" />
    <jointpos name="right_ankle_roll_joint_pos" joint="right_ankle_roll_joint" />
    <jointpos name="waist_yaw_joint_pos" joint="waist_yaw_joint" />
    <jointpos name="waist_roll_joint_pos" joint="waist_roll_joint" />
    <jointpos name="waist_pitch_joint_pos" joint="waist_pitch_joint" />
    <jointpos name="left_shoulder_pitch_joint_pos" joint="left_shoulder_pitch_joint" />
    <jointpos name="left_shoulder_roll_joint_pos" joint="left_shoulder_roll_joint" />
    <jointpos name="left_shoulder_yaw_joint_pos" joint="left_shoulder_yaw_joint" />
    <jointpos name="left_elbow_joint_pos" joint="left_elbow_joint" />
    <jointpos name="left_wrist_roll_joint_pos" joint="left_wrist_roll_joint" />
    <jointpos name="left_wrist_pitch_joint_pos" joint="left_wrist_pitch_joint" />
    <jointpos name="left_wrist_yaw_joint_pos" joint="left_wrist_yaw_joint" />
    <jointpos name="left_thumb_1_joint_pos" joint="left_thumb_1_joint" />
    <jointpos name="left_thumb_2_joint_pos" joint="left_thumb_2_joint" />
    <jointpos name="left_thumb_3_joint_pos" joint="left_thumb_3_joint" />
    <jointpos name="left_thumb_4_joint_pos" joint="left_thumb_4_joint" />
    <jointpos name="left_index_1_joint_pos" joint="left_index_1_joint" />
    <jointpos name="left_index_2_joint_pos" joint="left_index_2_joint" />
    <jointpos name="left_middle_1_joint_pos" joint="left_middle_1_joint" />
    <jointpos name="left_middle_2_joint_pos" joint="left_middle_2_joint" />
    <jointpos name="left_ring_1_joint_pos" joint="left_ring_1_joint" />
    <jointpos name="left_ring_2_joint_pos" joint="left_ring_2_joint" />
    <jointpos name="left_little_1_joint_pos" joint="left_little_1_joint" />
    <jointpos name="left_little_2_joint_pos" joint="left_little_2_joint" />
    <jointpos name="right_shoulder_pitch_joint_pos" joint="right_shoulder_pitch_joint" />
    <jointpos name="right_shoulder_roll_joint_pos" joint="right_shoulder_roll_joint" />
    <jointpos name="right_shoulder_yaw_joint_pos" joint="right_shoulder_yaw_joint" />
    <jointpos name="right_elbow_joint_pos" joint="right_elbow_joint" />
    <jointpos name="right_wrist_roll_joint_pos" joint="right_wrist_roll_joint" />
    <jointpos name="right_wrist_pitch_joint_pos" joint="right_wrist_pitch_joint" />
    <jointpos name="right_wrist_yaw_joint_pos" joint="right_wrist_yaw_joint" />
    <jointpos name="right_thumb_1_joint_pos" joint="right_thumb_1_joint" />
    <jointpos name="right_thumb_2_joint_pos" joint="right_thumb_2_joint" />
    <jointpos name="right_thumb_3_joint_pos" joint="right_thumb_3_joint" />
    <jointpos name="right_thumb_4_joint_pos" joint="right_thumb_4_joint" />
    <jointpos name="right_index_1_joint_pos" joint="right_index_1_joint" />
    <jointpos name="right_index_2_joint_pos" joint="right_index_2_joint" />
    <jointpos name="right_middle_1_joint_pos" joint="right_middle_1_joint" />
    <jointpos name="right_middle_2_joint_pos" joint="right_middle_2_joint" />
    <jointpos name="right_ring_1_joint_pos" joint="right_ring_1_joint" />
    <jointpos name="right_ring_2_joint_pos" joint="right_ring_2_joint" />
    <jointpos name="right_little_1_joint_pos" joint="right_little_1_joint" />
    <jointpos name="right_little_2_joint_pos" joint="right_little_2_joint" />
    
    <jointvel name="left_hip_pitch_joint_vel" joint="left_hip_pitch_joint" />
    <jointvel name="left_hip_roll_joint_vel" joint="left_hip_roll_joint" />
    <jointvel name="left_hip_yaw_joint_vel" joint="left_hip_yaw_joint" />
    <jointvel name="left_knee_joint_vel" joint="left_knee_joint" />
    <jointvel name="left_ankle_pitch_joint_vel" joint="left_ankle_pitch_joint" />
    <jointvel name="left_ankle_roll_joint_vel" joint="left_ankle_roll_joint" />
    <jointvel name="right_hip_pitch_joint_vel" joint="right_hip_pitch_joint" />
    <jointvel name="right_hip_roll_joint_vel" joint="right_hip_roll_joint" />
    <jointvel name="right_hip_yaw_joint_vel" joint="right_hip_yaw_joint" />
    <jointvel name="right_knee_joint_vel" joint="right_knee_joint" />
    <jointvel name="right_ankle_pitch_joint_vel" joint="right_ankle_pitch_joint" />
    <jointvel name="right_ankle_roll_joint_vel" joint="right_ankle_roll_joint" />
    <jointvel name="waist_yaw_joint_vel" joint="waist_yaw_joint" />
    <jointvel name="waist_roll_joint_vel" joint="waist_roll_joint" />
    <jointvel name="waist_pitch_joint_vel" joint="waist_pitch_joint" />
    <jointvel name="left_shoulder_pitch_joint_vel" joint="left_shoulder_pitch_joint" />
    <jointvel name="left_shoulder_roll_joint_vel" joint="left_shoulder_roll_joint" />
    <jointvel name="left_shoulder_yaw_joint_vel" joint="left_shoulder_yaw_joint" />
    <jointvel name="left_elbow_joint_vel" joint="left_elbow_joint" />
    <jointvel name="left_wrist_roll_joint_vel" joint="left_wrist_roll_joint" />
    <jointvel name="left_wrist_pitch_joint_vel" joint="left_wrist_pitch_joint" />
    <jointvel name="left_wrist_yaw_joint_vel" joint="left_wrist_yaw_joint" />
    <jointvel name="left_thumb_1_joint_vel" joint="left_thumb_1_joint" />
    <jointvel name="left_thumb_2_joint_vel" joint="left_thumb_2_joint" />
    <jointvel name="left_thumb_3_joint_vel" joint="left_thumb_3_joint" />
    <jointvel name="left_thumb_4_joint_vel" joint="left_thumb_4_joint" />
    <jointvel name="left_index_1_joint_vel" joint="left_index_1_joint" />
    <jointvel name="left_index_2_joint_vel" joint="left_index_2_joint" />
    <jointvel name="left_middle_1_joint_vel" joint="left_middle_1_joint" />
    <jointvel name="left_middle_2_joint_vel" joint="left_middle_2_joint" />
    <jointvel name="left_ring_1_joint_vel" joint="left_ring_1_joint" />
    <jointvel name="left_ring_2_joint_vel" joint="left_ring_2_joint" />
    <jointvel name="left_little_1_joint_vel" joint="left_little_1_joint" />
    <jointvel name="left_little_2_joint_vel" joint="left_little_2_joint" />
    <jointvel name="right_shoulder_pitch_joint_vel" joint="right_shoulder_pitch_joint" />
    <jointvel name="right_shoulder_roll_joint_vel" joint="right_shoulder_roll_joint" />
    <jointvel name="right_shoulder_yaw_joint_vel" joint="right_shoulder_yaw_joint" />
    <jointvel name="right_elbow_joint_vel" joint="right_elbow_joint" />
    <jointvel name="right_wrist_roll_joint_vel" joint="right_wrist_roll_joint" />
    <jointvel name="right_wrist_pitch_joint_vel" joint="right_wrist_pitch_joint" />
    <jointvel name="right_wrist_yaw_joint_vel" joint="right_wrist_yaw_joint" />
    <jointvel name="right_thumb_1_joint_vel" joint="right_thumb_1_joint" />
    <jointvel name="right_thumb_2_joint_vel" joint="right_thumb_2_joint" />
    <jointvel name="right_thumb_3_joint_vel" joint="right_thumb_3_joint" />
    <jointvel name="right_thumb_4_joint_vel" joint="right_thumb_4_joint" />
    <jointvel name="right_index_1_joint_vel" joint="right_index_1_joint" />
    <jointvel name="right_index_2_joint_vel" joint="right_index_2_joint" />
    <jointvel name="right_middle_1_joint_vel" joint="right_middle_1_joint" />
    <jointvel name="right_middle_2_joint_vel" joint="right_middle_2_joint" />
    <jointvel name="right_ring_1_joint_vel" joint="right_ring_1_joint" />
    <jointvel name="right_ring_2_joint_vel" joint="right_ring_2_joint" />
    <jointvel name="right_little_1_joint_vel" joint="right_little_1_joint" />
    <jointvel name="right_little_2_joint_vel" joint="right_little_2_joint" />
    
    <jointactuatorfrc name="left_hip_pitch_joint_torque" joint="left_hip_pitch_joint" />
    <jointactuatorfrc name="left_hip_roll_joint_torque" joint="left_hip_roll_joint" />
    <jointactuatorfrc name="left_hip_yaw_joint_torque" joint="left_hip_yaw_joint" />
    <jointactuatorfrc name="left_knee_joint_torque" joint="left_knee_joint" />
    <jointactuatorfrc name="left_ankle_pitch_joint_torque" joint="left_ankle_pitch_joint" />
    <jointactuatorfrc name="left_ankle_roll_joint_torque" joint="left_ankle_roll_joint" />
    <jointactuatorfrc name="right_hip_pitch_joint_torque" joint="right_hip_pitch_joint" />
    <jointactuatorfrc name="right_hip_roll_joint_torque" joint="right_hip_roll_joint" />
    <jointactuatorfrc name="right_hip_yaw_joint_torque" joint="right_hip_yaw_joint" />
    <jointactuatorfrc name="right_knee_joint_torque" joint="right_knee_joint" />
    <jointactuatorfrc name="right_ankle_pitch_joint_torque" joint="right_ankle_pitch_joint" />
    <jointactuatorfrc name="right_ankle_roll_joint_torque" joint="right_ankle_roll_joint" />
    <jointactuatorfrc name="waist_yaw_joint_torque" joint="waist_yaw_joint" />
    <jointactuatorfrc name="waist_roll_joint_torque" joint="waist_roll_joint" />
    <jointactuatorfrc name="waist_pitch_joint_torque" joint="waist_pitch_joint" />
    <jointactuatorfrc name="left_shoulder_pitch_joint_torque" joint="left_shoulder_pitch_joint" />
    <jointactuatorfrc name="left_shoulder_roll_joint_torque" joint="left_shoulder_roll_joint" />
    <jointactuatorfrc name="left_shoulder_yaw_joint_torque" joint="left_shoulder_yaw_joint" />
    <jointactuatorfrc name="left_elbow_joint_torque" joint="left_elbow_joint" />
    <jointactuatorfrc name="left_wrist_roll_joint_torque" joint="left_wrist_roll_joint" />
    <jointactuatorfrc name="left_wrist_pitch_joint_torque" joint="left_wrist_pitch_joint" />
    <jointactuatorfrc name="left_wrist_yaw_joint_torque" joint="left_wrist_yaw_joint" />
    <jointactuatorfrc name="left_thumb_1_joint_torque" joint="left_thumb_1_joint" />
    <jointactuatorfrc name="left_thumb_2_joint_torque" joint="left_thumb_2_joint" />
    <jointactuatorfrc name="left_thumb_3_joint_torque" joint="left_thumb_3_joint" />
    <jointactuatorfrc name="left_thumb_4_joint_torque" joint="left_thumb_4_joint" />
    <jointactuatorfrc name="left_index_1_joint_torque" joint="left_index_1_joint" />
    <jointactuatorfrc name="left_index_2_joint_torque" joint="left_index_2_joint" />
    <jointactuatorfrc name="left_middle_1_joint_torque" joint="left_middle_1_joint" />
    <jointactuatorfrc name="left_middle_2_joint_torque" joint="left_middle_2_joint" />
    <jointactuatorfrc name="left_ring_1_joint_torque" joint="left_ring_1_joint" />
    <jointactuatorfrc name="left_ring_2_joint_torque" joint="left_ring_2_joint" />
    <jointactuatorfrc name="left_little_1_joint_torque" joint="left_little_1_joint" />
    <jointactuatorfrc name="left_little_2_joint_torque" joint="left_little_2_joint" />
    <jointactuatorfrc name="right_shoulder_pitch_joint_torque" joint="right_shoulder_pitch_joint" />
    <jointactuatorfrc name="right_shoulder_roll_joint_torque" joint="right_shoulder_roll_joint" />
    <jointactuatorfrc name="right_shoulder_yaw_joint_torque" joint="right_shoulder_yaw_joint" />
    <jointactuatorfrc name="right_elbow_joint_torque" joint="right_elbow_joint" />
    <jointactuatorfrc name="right_wrist_roll_joint_torque" joint="right_wrist_roll_joint" />
    <jointactuatorfrc name="right_wrist_pitch_joint_torque" joint="right_wrist_pitch_joint" />
    <jointactuatorfrc name="right_wrist_yaw_joint_torque" joint="right_wrist_yaw_joint" />
    <jointactuatorfrc name="right_thumb_1_joint_torque" joint="right_thumb_1_joint" />
    <jointactuatorfrc name="right_thumb_2_joint_torque" joint="right_thumb_2_joint" />
    <jointactuatorfrc name="right_thumb_3_joint_torque" joint="right_thumb_3_joint" />
    <jointactuatorfrc name="right_thumb_4_joint_torque" joint="right_thumb_4_joint" />
    <jointactuatorfrc name="right_index_1_joint_torque" joint="right_index_1_joint" />
    <jointactuatorfrc name="right_index_2_joint_torque" joint="right_index_2_joint" />
    <jointactuatorfrc name="right_middle_1_joint_torque" joint="right_middle_1_joint" />
    <jointactuatorfrc name="right_middle_2_joint_torque" joint="right_middle_2_joint" />
    <jointactuatorfrc name="right_ring_1_joint_torque" joint="right_ring_1_joint" />
    <jointactuatorfrc name="right_ring_2_joint_torque" joint="right_ring_2_joint" />
    <jointactuatorfrc name="right_little_1_joint_torque" joint="right_little_1_joint" />
    <jointactuatorfrc name="right_little_2_joint_torque" joint="right_little_2_joint" />
    
    <framequat name="imu_quat" objtype="site" objname="imu" />
    <gyro name="imu_gyro" site="imu" />
    <accelerometer name="imu_acc" site="imu" />

    <framepos name="frame_pos" objtype="site" objname="imu" />
    <framelinvel name="frame_vel" objtype="site" objname="imu" />
  </sensor>

  <asset>
    <texture type="skybox" builtin="flat" rgb1="0 0 0" rgb2="0 0 0" width="512" height="3072"/>
    <texture type="2d" name="groundplane" builtin="checker" mark="edge" rgb1="0.2 0.3 0.4" rgb2="0.1 0.2 0.3" markrgb="0.8 0.8 0.8" width="300" height="300"/>
    <material name="groundplane" texture="groundplane" texuniform="true" texrepeat="5 5" reflectance="0.2"/>
  </asset>

  <worldbody>
    <light pos="1 0 3.5" dir="0 0 -1" directional="true"/>
    <geom name="floor" size="0 0 0.05" type="plane" material="groundplane"/>
  </worldbody>


</mujoco>
